Workbook

Sheet Начало
A1: СТАНДАРТИЗИРОВАННАЯ РАБОТА / И-ГЦ-02
A2: ДЕМО / ПРОЕКТ • Жёлтые ячейки — ваш ввод. Расчёты не являются утверждёнными нормативами.
A3: ← Начало
A4: Готовая расчётная модель: 18 продуктов · 3 программы SOLIA · 11 бланков ФЦК · критерии качества и чек-лист СОП. Все демонстрационные числа подписаны, обязательная технология отделена от предположений.
A7: 1. Откройте «Ввод» и «Ассортимент». Замените жёлтые значения своими. 2. Внесите реальные замеры в оба набора наблюдений и периодическую работу. 3. Проверьте «Контроль». Подробные бланки переключаются выбором продукта во «Ввод».
A10: План годного, кг | C10: ='Ассортимент'!F27 -> 107 | E10: ЖЁЛТЫЙ = ввод: заменяйте числа и текст. СИНИЙ = формулы: пересчёт автоматический. СЕРЫЙ = требования источника: не менять ради улучшений.
A11: Партий в смену | C11: ='Ввод'!B28 -> 32
A12: Доступно времени, с | C12: ='Ввод'!B27 -> 24600
A13: Такт, с/партию | C13: ='Ввод'!B30 -> 768.75
A14: Полных санобработок, событий | C14: ='Периодическая работа'!B20 -> 8 | E14: Модель исходно предполагает 1 машину и 1 оператора без перекрытия ручной работы с автоматической. Изменение числа ресурсов не строит новый производственный график. Подписи, обучение, результаты проверок и факты внедрения не вымышлены.
A15: Время ДО, мин/смену | C15: =IF(ISNUMBER('Расчет ДО'!B33),'Расчет ДО'!B33/60,"") -> 409.86267
A16: Время ЦЕЛЬ, мин/смену | C16: =IF(ISNUMBER('Расчет ЦЕЛЬ'!B33),'Расчет ЦЕЛЬ'!B33/60,"") -> 387.568
A17: Прогноз высвобождения, мин/смену | C17: ='Отчет об улучшении'!D28 -> 22.294667
A18: Критических ошибок ввода/формул | C18: ='Контроль'!C37 -> 0
A21: № | B21: Лист / раздел | C21: Назначение | D21: Где менять
A22: 1 | B22: Ввод | C22: Смена, ресурсы, реквизиты, выбор продукта | G22: Жёлтые клетки B
A23: 2 | B23: Режимы И-ГЦ-02 | C23: Неизменяемые программы мойки | G23: Серые требования источника
A24: 3 | B24: Ассортимент | C24: План, выходы, партии, сырьё и остатки | G24: F8:J25
A25: 4 | B25: Замеры ДО | C25: 10 замеров × 18 продуктов, исходная модель | G25: Жёлтые E:N каждого блока
A26: 5 | B26: Замеры ЦЕЛЬ | C26: Прогнозные / контрольные замеры | G26: Жёлтые E:N каждого блока
A27: 6 | B27: Периодическая работа | C27: Санобработка и подача тары | G27: Жёлтые длительности / частота тары
A28: 7 | B28: Расчет ДО | C28: Сводная нагрузка исходного состояния | G28: Формулы
A29: 8 | B29: Расчет ЦЕЛЬ | C29: Сводная нагрузка прогноза | G29: Формулы
A30: 9 | B30: Время такта | C30: Форма 1: такт по всем видам | G30: Ввод / Ассортимент
A31: 10 | B31: Лист наблюдений | C31: Форма 2: общие времена циклов | G31: Продукт / сценарий во Ввод
A32: 11 | B32: Ручная работа | C32: Форма 4: поэлементная регулировка | G32: Продукт / сценарий во Ввод
A33: 12 | B33: Карта СР | C33: Форма 3: маршрут, качество, безопасность, запас | G33: Жёлтые координаты C:F
... A48: 27 | B48: Лист ознакомления | C48: Реальные обучение и подписи | G48: Жёлтые поля после обучения
A51: Использование: Microsoft Excel (автовычисление включено) или LibreOffice Calc. Макросы не нужны. Формулы защищены без пароля от случайного изменения. Исходные PDF/XLSX лежат в sources/; книга представляет расчётную адаптацию шаблонов, а не изменённую методику.
A55: Перед вводом в работу: заменить ДЕМО-замеры, проверить состав этапов и натурную планировку, уточнить СИЗ и режимы санитарных средств, провести контрольные наблюдения, согласовать/утвердить СОП и обучить персонал. Числа прогноза не являются фактом внедрения и не подтверждают безопасность или соответствие стандартам.

Sheet Ввод
A1: 01 / ИСХОДНЫЕ ДАННЫЕ И ВЫБОР ПРОДУКТА
A2: ДЕМО / ПРОЕКТ • Жёлтые ячейки — ваш ввод. Расчёты не являются утверждёнными нормативами.
A3: ← Начало | B3: Синий фон — формула; серый — инструкция; жёлтый — ввод. Защита снимается без пароля.
A5: Параметр | B5: Ваше значение | C5: Единица | D5: Что заменить / источник
A6: Предприятие | B6: АО «ПП «Русский хлеб» — уточнить юрлицо | D6: В титуле И-ГЦ-02 также указано ООО «Курортное кафе». Перед утверждением сверить реквизиты.
A7: Цех | B7: Кулинарный цех | D7: Уточнить наименование цеха.
A8: Рабочее место | B8: Овощной участок / SOLIA | D8: Фактическое рабочее место и инвентарный номер оборудования.
A9: Подготовил | B9: Впишите ФИО составителя | D9: Без вымышленных подписей и подтверждения проведения наблюдений.
A10: Дата начала проекта | B10: 46270 | C10: дата | D10: Демонстрационная дата; от неё рассчитываются плановые сроки.
A11: Принятый тип работы | B11: II — многономенклатурная работа | C11: II | D11: Принят для модели; подтвердить наблюдением. Внутри каждого продукта используется поэлементный подход I типа.
A12: Продукт для подробных бланков | B12: Латук | D12: Выбор перестраивает наблюдения, ручную работу, ОТ, карту и СОП. Общие расчёты всегда учитывают все 18 продуктов.
A13: Сценарий подробных наблюдений | B13: ДО | D13: ДО — модель исходного состояния; ЦЕЛЬ — прогноз. Ни один не является фактом до замены замеров.
A14: Основание данных ДО | B14: ДЕМО: синтетические замеры; заменить фактическими | D14: Укажите дату, смену, исполнителя и ссылку на лист/видеозапись реальных замеров.
A15: Основание данных ЦЕЛЬ | B15: ДЕМО: прогноз; улучшения не внедрены | D15: Не переименовывать прогноз в факт без контрольных наблюдений.
A17: Продолжительность одной смены | B17: 480 | C17: мин/смену | D17: Модель рассчитывает ОДНУ смену. Для разных смен используйте отдельные копии книги.
A18: Обед | B18: 30 | C18: мин/смену | D18: Только регламентированное время. Не включайте сюда периодическую санобработку.
A19: Прочие регламентные перерывы | B19: 20 | C19: мин/смену | D19: Сумма перерывов; не учитывать повторно в периодической работе.
A20: Фиксированная подготовка смены | B20: 10 | C20: мин/смену | D20: Не включает подачу тары и санобработку бака, учтённые отдельно.
A21: Фиксированное завершение смены | B21: 10 | C21: мин/смену | D21: Не включает санобработку бака. Она целиком находится в периодической работе.
A22: Доступно моечных машин | B22: 1 | C22: ед. | D22: При значении не 1 ресурсные оценки агрегированные. ОТ и карта описывают только одну ячейку; нужен фактический график распределения.
A23: Операторов в смене | B23: 1 | C23: чел. | D23: В базовой схеме оператор не выполняет другую работу во время автоматической программы. Дополнительные люди не ускоряют машину автоматически.
A24: Обязательная периодичность санобработки | B24: 4 | C24: 4 помывки | D24: И-ГЦ-02, стр. 3. Частота — требование источника, не объект оптимизации.
A25: Помывок с последней санобработки к началу смены | B25: 0 | C25: 0…3 | D25: Фактический счётчик. 0 означает подготовленный чистый бак. Для неполного предыдущего блока введите 1–3.
A26: Резерв завершающей санобработки неполного блока | B26: 1 | C26: 1 / 0 | D26: ДЕМО: 1 — резерв полного комплекса после неполной четвёрки в конце смены. Это плановое допущение; уточнить по санпрограмме. Регулярную обработку после 4 помывок отключить нельзя.
A27: Фонд рабочего времени одной ячейки | B27: =IF(AND(COUNT(B17:B21)=5,MIN(B17:B21)>=0,B17>SUM(B18:B21)),(B17-SUM(B18:B21))*60,"") -> 24600 | C27: с/смену
A28: Всего партий в плане | B28: =IF(COUNT('Ассортимент'!O8:O25)=18,'Ассортимент'!O27,"") -> 32 | C28: партий/смену
A29: Индекс выбранного продукта | B29: =IFERROR(MATCH(B12,'Ассортимент'!B8:B25,0),0) -> 1
A30: Такт выпуска по всему ассортименту | B30: =IF(AND(ISNUMBER(B27),B27>0,ISNUMBER(B28),B28>0),B27/B28,"") -> 768.75 | C30: с/партию
A33: Ответственный за внедрение | B33: Начальник кулинарного цеха — впишите ФИО | D33: Проект распределения ролей, не назначение приказом.
A34: Ответственный за технологию | B34: Инженер-технолог — впишите ФИО | D34: Проверяет режимы, нормы загрузки, санпрограмму и качество.
A35: Исполнитель | B35: Оператор SOLIA — впишите ФИО | D35: Указать реально наблюдаемого и обученного исполнителя.
A36: Ответственный за ОТ | B36: Ответственный по ОТ — впишите ФИО | D36: Согласовать безопасные действия, СИЗ, инструкции и допуск.
A37: Утверждает | B37: Уполномоченный руководитель — впишите ФИО | D37: Утверждение выполняется вне расчётной модели в установленном порядке.
A38: Статус утверждения | B38: Не утверждено | D38: Редактировать только после реального согласования и утверждения; подпись не генерируется.
A40: Номер улучшения для отчёта | B40: 1 | C40: 1…6 | D40: Переключает подробный отчёт об улучшении.
A42: Проверяйте лист «Контроль» после каждого изменения. Количество людей не умножает время такта. Для нескольких ячеек нужна отдельная балансировка и распределение целых партий.

Sheet Режимы И-ГЦ-02
A1: 02 / ТЕХНОЛОГИЧЕСКИЕ ДАННЫЕ ИЗ ИНСТРУКЦИИ
A2: ДЕМО / ПРОЕКТ • Жёлтые ячейки — ваш ввод. Расчёты не являются утверждёнными нормативами.
A3: ← Начало | B3: Синий фон — формула; серый — инструкция; жёлтый — ввод. Защита снимается без пароля.
A7: Программа | B7: Мытьё, об/мин | C7: Мытьё, с | D7: Ополаск., об/мин | E7: Ополаск., с | F7: Вращение, об/мин | G7: Вращение, с | H7: Всего авто, с | I7: Тара после обработки | J7: Источник
A8: 1 | B8: 30 | C8: 60 | D8: 150 | E8: 30 | F8: 400 | G8: 360 | H8: =SUM(C8,E8,G8) -> 450 | I8: «ЗЕЛЕНЬ» для зелени; «СО» для овощей | J8: И-ГЦ-02, PDF стр. 3, таблица №1
A9: 2 | B9: 30 | C9: 60 | D9: 150 | E9: 60 | F9: 150 | G9: 60 | H9: =SUM(C9,E9,G9) -> 180 | I9: «ЗЕЛЕНЬ» для зелени; «СО» для овощей | J9: И-ГЦ-02, PDF стр. 3, таблица №1
A10: 3 | B10: 30 | C10: 120 | D10: 150 | E10: 60 | F10: 250 | G10: 120 | H10: =SUM(C10,E10,G10) -> 300 | I10: «ЗЕЛЕНЬ» для зелени; «СО» для овощей | J10: И-ГЦ-02, PDF стр. 3, таблица №1
A13: ВАЖНО: 01 = 450 с; 02 = 180 с; 03 = 300 с. Значения «1:00 мин:сек» переведены в 60 секунд, «6:00» — в 360 секунд. Это не 1 и не 6 секунд.
A16: После каждой 4-й помывки: слить бак → после слива выключить и обесточить оборудование → промыть бак моющими средствами и продезинфицировать. В книге это отдельный периодический комплекс, а не вычет из фонда времени.
A20: И-ГЦ-02 не задаёт средство, концентрацию, температуру и экспозицию дезинфекции, перечень СИЗ и длительности ручных действий. Они НЕ придуманы как технологические нормы. Демонстрационное время в периодических замерах служит только иллюстрацией расчёта.
A24: Названия и загрузки всех 18 позиций перенесены в «Ассортимент». Группировка для расчёта — проектная; отдельные названия («сельдерей ствол») сохранены как в источнике. Предел трактуется консервативно как верхняя масса одной загрузки.

Sheet Ассортимент
A1: 03 / ПЛАН СМЕНЫ · МАССОВЫЙ БАЛАНС · ЧИСЛО ПАРТИЙ
A2: ДЕМО / ПРОЕКТ • Жёлтые ячейки — ваш ввод. Расчёты не являются утверждёнными нормативами.
A3: ← Начало | B3: Синий фон — формула; серый — инструкция; жёлтый — ввод. Защита снимается без пароля.
A5: Меняйте F:J. План задаётся в кг годного после мойки. Выход подготовки и выход мойки — разные показатели. Партии считаются по массе, поступающей непосредственно в SOLIA.
A7: № | B7: Продукт | C7: Группа | D7: Программа | E7: Предел загрузки, кг | F7: План годного, кг | G7: Выход подготовки | H7: Выход мойки | I7: Партия план, кг | J7: Партия замера, кг | K7: В мойку, кг | L7: Исходное сырьё, кг | M7: Отсев до мойки, кг | N7: Потери при мойке, кг | O7: Партий, шт. | P7: Последняя партия, кг | Q7: Доля партий | R7: Авто, с/партию | S7: Контроль вводов | T7: Сопоставимость замеров
A8: 1 | B8: Латук | C8: Зелень | D8: 1 | E8: 1.5 | F8: 3 | G8: 0.95 | H8: 1 | I8: 1.5 | J8: 1.5 | K8: =IF(S8="ОК",F8/H8,"") -> 3 | L8: =IF(S8="ОК",K8/G8,"") -> 3.1578947 | M8: =IF(S8="ОК",L8-K8,"") -> 0.15789474 | N8: =IF(S8="ОК",K8-F8,"") -> 0 | O8: =IF(S8="ОК",ROUNDUP(ROUND(K8/I8,10),0),"") -> 2 | P8: =IF(S8="ОК",IF(O8>0,MAX(0,K8-(O8-1)*I8),0),"") -> 1.5 | Q8: =IF(AND(ISNUMBER(O8),ISNUMBER($O$27),$O$27>0),O8/$O$27,0) -> 0.0625 | R8: =VLOOKUP(D8,'Режимы И-ГЦ-02'!$A$8:$H$10,8,FALSE) -> 450 | S8: =IF(AND(COUNT(F8:J8)=5,F8>=0,G8>0,G8<=1,H8>0,H8<=1,I8>0,I8<=E8,J8>0,J8<=E8),"ОК","ОШИБКА: проверьте F:J") -> ОК | T8: =IF(S8<>"ОК","Исправьте ввод",IF(F8=0,"Нет в плане",IF(ABS(I8-J8)<0.000001,"Партия совпадает","НУЖЕН НОВЫЙ ХРОНОМЕТРАЖ"))) -> Партия совпадает
A9: 2 | B9: Базилик | C9: Зелень | D9: 1 | E9: 1.5 | F9: 1.5 | G9: 0.95 | H9: 1 | I9: 1.5 | J9: 1.5 | K9: =IF(S9="ОК",F9/H9,"") -> 1.5 | L9: =IF(S9="ОК",K9/G9,"") -> 1.5789474 | M9: =IF(S9="ОК",L9-K9,"") -> 0.078947368 | N9: =IF(S9="ОК",K9-F9,"") -> 0 | O9: =IF(S9="ОК",ROUNDUP(ROUND(K9/I9,10),0),"") -> 1 | P9: =IF(S9="ОК",IF(O9>0,MAX(0,K9-(O9-1)*I9),0),"") -> 1.5 | Q9: =IF(AND(ISNUMBER(O9),ISNUMBER($O$27),$O$27>0),O9/$O$27,0) -> 0.03125 | R9: =VLOOKUP(D9,'Режимы И-ГЦ-02'!$A$8:$H$10,8,FALSE) -> 450 | S9: =IF(AND(COUNT(F9:J9)=5,F9>=0,G9>0,G9<=1,H9>0,H9<=1,I9>0,I9<=E9,J9>0,J9<=E9),"ОК","ОШИБКА: проверьте F:J") -> ОК | T9: =IF(S9<>"ОК","Исправьте ввод",IF(F9=0,"Нет в плане",IF(ABS(I9-J9)<0.000001,"Партия совпадает","НУЖЕН НОВЫЙ ХРОНОМЕТРАЖ"))) -> Партия совпадает
A10: 3 | B10: Петрушка | C10: Зелень | D10: 1 | E10: 1.5 | F10: 1.5 | G10: 0.95 | H10: 1 | I10: 1.5 | J10: 1.5 | K10: =IF(S10="ОК",F10/H10,"") -> 1.5 | L10: =IF(S10="ОК",K10/G10,"") -> 1.5789474 | M10: =IF(S10="ОК",L10-K10,"") -> 0.078947368 | N10: =IF(S10="ОК",K10-F10,"") -> 0 | O10: =IF(S10="ОК",ROUNDUP(ROUND(K10/I10,10),0),"") -> 1 | P10: =IF(S10="ОК",IF(O10>0,MAX(0,K10-(O10-1)*I10),0),"") -> 1.5 | Q10: =IF(AND(ISNUMBER(O10),ISNUMBER($O$27),$O$27>0),O10/$O$27,0) -> 0.03125 | R10: =VLOOKUP(D10,'Режимы И-ГЦ-02'!$A$8:$H$10,8,FALSE) -> 450 | S10: =IF(AND(COUNT(F10:J10)=5,F10>=0,G10>0,G10<=1,H10>0,H10<=1,I10>0,I10<=E10,J10>0,J10<=E10),"ОК","ОШИБКА: проверьте F:J") -> ОК | T10: =IF(S10<>"ОК","Исправьте ввод",IF(F10=0,"Нет в плане",IF(ABS(I10-J10)<0.000001,"Партия совпадает","НУЖЕН НОВЫЙ ХРОНОМЕТРАЖ"))) -> Партия совпадает
A11: 4 | B11: Томат | C11: Овощи и прочее | D11: 2 | E11: 5 | F11: 25 | G11: 0.98 | H11: 1 | I11: 5 | J11: 5 | K11: =IF(S11="ОК",F11/H11,"") -> 25 | L11: =IF(S11="ОК",K11/G11,"") -> 25.510204 | M11: =IF(S11="ОК",L11-K11,"") -> 0.51020408 | N11: =IF(S11="ОК",K11-F11,"") -> 0 | O11: =IF(S11="ОК",ROUNDUP(ROUND(K11/I11,10),0),"") -> 5 | P11: =IF(S11="ОК",IF(O11>0,MAX(0,K11-(O11-1)*I11),0),"") -> 5 | Q11: =IF(AND(ISNUMBER(O11),ISNUMBER($O$27),$O$27>0),O11/$O$27,0) -> 0.15625 | R11: =VLOOKUP(D11,'Режимы И-ГЦ-02'!$A$8:$H$10,8,FALSE) -> 180 | S11: =IF(AND(COUNT(F11:J11)=5,F11>=0,G11>0,G11<=1,H11>0,H11<=1,I11>0,I11<=E11,J11>0,J11<=E11),"ОК","ОШИБКА: проверьте F:J") -> ОК | T11: =IF(S11<>"ОК","Исправьте ввод",IF(F11=0,"Нет в плане",IF(ABS(I11-J11)<0.000001,"Партия совпадает","НУЖЕН НОВЫЙ ХРОНОМЕТРАЖ"))) -> Партия совпадает
A12: 5 | B12: Белокочанная капуста | C12: Овощи и прочее | D12: 2 | E12: 3 | F12: 9 | G12: 0.98 | H12: 1 | I12: 3 | J12: 3 | K12: =IF(S12="ОК",F12/H12,"") -> 9 | L12: =IF(S12="ОК",K12/G12,"") -> 9.1836735 | M12: =IF(S12="ОК",L12-K12,"") -> 0.18367347 | N12: =IF(S12="ОК",K12-F12,"") -> 0 | O12: =IF(S12="ОК",ROUNDUP(ROUND(K12/I12,10),0),"") -> 3 | P12: =IF(S12="ОК",IF(O12>0,MAX(0,K12-(O12-1)*I12),0),"") -> 3 | Q12: =IF(AND(ISNUMBER(O12),ISNUMBER($O$27),$O$27>0),O12/$O$27,0) -> 0.09375 | R12: =VLOOKUP(D12,'Режимы И-ГЦ-02'!$A$8:$H$10,8,FALSE) -> 180 | S12: =IF(AND(COUNT(F12:J12)=5,F12>=0,G12>0,G12<=1,H12>0,H12<=1,I12>0,I12<=E12,J12>0,J12<=E12),"ОК","ОШИБКА: проверьте F:J") -> ОК | T12: =IF(S12<>"ОК","Исправьте ввод",IF(F12=0,"Нет в плане",IF(ABS(I12-J12)<0.000001,"Партия совпадает","НУЖЕН НОВЫЙ ХРОНОМЕТРАЖ"))) -> Партия совпадает
A13: 6 | B13: Укроп | C13: Зелень | D13: 3 | E13: 1.5 | F13: 3 | G13: 0.95 | H13: 1 | I13: 1.5 | J13: 1.5 | K13: =IF(S13="ОК",F13/H13,"") -> 3 | L13: =IF(S13="ОК",K13/G13,"") -> 3.1578947 | M13: =IF(S13="ОК",L13-K13,"") -> 0.15789474 | N13: =IF(S13="ОК",K13-F13,"") -> 0 | O13: =IF(S13="ОК",ROUNDUP(ROUND(K13/I13,10),0),"") -> 2 | P13: =IF(S13="ОК",IF(O13>0,MAX(0,K13-(O13-1)*I13),0),"") -> 1.5 | Q13: =IF(AND(ISNUMBER(O13),ISNUMBER($O$27),$O$27>0),O13/$O$27,0) -> 0.0625 | R13: =VLOOKUP(D13,'Режимы И-ГЦ-02'!$A$8:$H$10,8,FALSE) -> 300 | S13: =IF(AND(COUNT(F13:J13)=5,F13>=0,G13>0,G13<=1,H13>0,H13<=1,I13>0,I13<=E13,J13>0,J13<=E13),"ОК","ОШИБКА: проверьте F:J") -> ОК | T13: =IF(S13<>"ОК","Исправьте ввод",IF(F13=0,"Нет в плане",IF(ABS(I13-J13)<0.000001,"Партия совпадает","НУЖЕН НОВЫЙ ХРОНОМЕТРАЖ"))) -> Партия совпадает
A14: 7 | B14: Зеленый лук | C14: Зелень | D14: 3 | E14: 1.5 | F14: 1.5 | G14: 0.95 | H14: 1 | I14: 1.5 | J14: 1.5 | K14: =IF(S14="ОК",F14/H14,"") -> 1.5 | L14: =IF(S14="ОК",K14/G14,"") -> 1.5789474 | M14: =IF(S14="ОК",L14-K14,"") -> 0.078947368 | N14: =IF(S14="ОК",K14-F14,"") -> 0 | O14: =IF(S14="ОК",ROUNDUP(ROUND(K14/I14,10),0),"") -> 1 | P14: =IF(S14="ОК",IF(O14>0,MAX(0,K14-(O14-1)*I14),0),"") -> 1.5 | Q14: =IF(AND(ISNUMBER(O14),ISNUMBER($O$27),$O$27>0),O14/$O$27,0) -> 0.03125 | R14: =VLOOKUP(D14,'Режимы И-ГЦ-02'!$A$8:$H$10,8,FALSE) -> 300 | S14: =IF(AND(COUNT(F14:J14)=5,F14>=0,G14>0,G14<=1,H14>0,H14<=1,I14>0,I14<=E14,J14>0,J14<=E14),"ОК","ОШИБКА: проверьте F:J") -> ОК | T14: =IF(S14<>"ОК","Исправьте ввод",IF(F14=0,"Нет в плане",IF(ABS(I14-J14)<0.000001,"Партия совпадает","НУЖЕН НОВЫЙ ХРОНОМЕТРАЖ"))) -> Партия совпадает
A15: 8 | B15: Кинза | C15: Зелень | D15: 3 | E15: 1.5 | F15: 1.5 | G15: 0.95 | H15: 1 | I15: 1.5 | J15: 1.5 | K15: =IF(S15="ОК",F15/H15,"") -> 1.5 | L15: =IF(S15="ОК",K15/G15,"") -> 1.5789474 | M15: =IF(S15="ОК",L15-K15,"") -> 0.078947368 | N15: =IF(S15="ОК",K15-F15,"") -> 0 | O15: =IF(S15="ОК",ROUNDUP(ROUND(K15/I15,10),0),"") -> 1 | P15: =IF(S15="ОК",IF(O15>0,MAX(0,K15-(O15-1)*I15),0),"") -> 1.5 | Q15: =IF(AND(ISNUMBER(O15),ISNUMBER($O$27),$O$27>0),O15/$O$27,0) -> 0.03125 | R15: =VLOOKUP(D15,'Режимы И-ГЦ-02'!$A$8:$H$10,8,FALSE) -> 300 | S15: =IF(AND(COUNT(F15:J15)=5,F15>=0,G15>0,G15<=1,H15>0,H15<=1,I15>0,I15<=E15,J15>0,J15<=E15),"ОК","ОШИБКА: проверьте F:J") -> ОК | T15: =IF(S15<>"ОК","Исправьте ввод",IF(F15=0,"Нет в плане",IF(ABS(I15-J15)<0.000001,"Партия совпадает","НУЖЕН НОВЫЙ ХРОНОМЕТРАЖ"))) -> Партия совпадает
A16: 9 | B16: Шампиньоны | C16: Овощи и прочее | D16: 3 | E16: 5 | F16: 10 | G16: 0.98 | H16: 1 | I16: 5 | J16: 5 | K16: =IF(S16="ОК",F16/H16,"") -> 10 | L16: =IF(S16="ОК",K16/G16,"") -> 10.204082 | M16: =IF(S16="ОК",L16-K16,"") -> 0.20408163 | N16: =IF(S16="ОК",K16-F16,"") -> 0 | O16: =IF(S16="ОК",ROUNDUP(ROUND(K16/I16,10),0),"") -> 2 | P16: =IF(S16="ОК",IF(O16>0,MAX(0,K16-(O16-1)*I16),0),"") -> 5 | Q16: =IF(AND(ISNUMBER(O16),ISNUMBER($O$27),$O$27>0),O16/$O$27,0) -> 0.0625 | R16: =VLOOKUP(D16,'Режимы И-ГЦ-02'!$A$8:$H$10,8,FALSE) -> 300 | S16: =IF(AND(COUNT(F16:J16)=5,F16>=0,G16>0,G16<=1,H16>0,H16<=1,I16>0,I16<=E16,J16>0,J16<=E16),"ОК","ОШИБКА: проверьте F:J") -> ОК | T16: =IF(S16<>"ОК","Исправьте ввод",IF(F16=0,"Нет в плане",IF(ABS(I16-J16)<0.000001,"Партия совпадает","НУЖЕН НОВЫЙ ХРОНОМЕТРАЖ"))) -> Партия совпадает
A17: 10 | B17: Перец болгарский красный | C17: Овощи и прочее | D17: 3 | E17: 5 | F17: 15 | G17: 0.98 | H17: 1 | I17: 5 | J17: 5 | K17: =IF(S17="ОК",F17/H17,"") -> 15 | L17: =IF(S17="ОК",K17/G17,"") -> 15.306122 | M17: =IF(S17="ОК",L17-K17,"") -> 0.30612245 | N17: =IF(S17="ОК",K17-F17,"") -> 0 | O17: =IF(S17="ОК",ROUNDUP(ROUND(K17/I17,10),0),"") -> 3 | P17: =IF(S17="ОК",IF(O17>0,MAX(0,K17-(O17-1)*I17),0),"") -> 5 | Q17: =IF(AND(ISNUMBER(O17),ISNUMBER($O$27),$O$27>0),O17/$O$27,0) -> 0.09375 | R17: =VLOOKUP(D17,'Режимы И-ГЦ-02'!$A$8:$H$10,8,FALSE) -> 300 | S17: =IF(AND(COUNT(F17:J17)=5,F17>=0,G17>0,G17<=1,H17>0,H17<=1,I17>0,I17<=E17,J17>0,J17<=E17),"ОК","ОШИБКА: проверьте F:J") -> ОК | T17: =IF(S17<>"ОК","Исправьте ввод",IF(F17=0,"Нет в плане",IF(ABS(I17-J17)<0.000001,"Партия совпадает","НУЖЕН НОВЫЙ ХРОНОМЕТРАЖ"))) -> Партия совпадает
A18: 11 | B18: Огурец | C18: Овощи и прочее | D18: 3 | E18: 5 | F18: 20 | G18: 0.98 | H18: 1 | I18: 5 | J18: 5 | K18: =IF(S18="ОК",F18/H18,"") -> 20 | L18: =IF(S18="ОК",K18/G18,"") -> 20.408163 | M18: =IF(S18="ОК",L18-K18,"") -> 0.40816327 | N18: =IF(S18="ОК",K18-F18,"") -> 0 | O18: =IF(S18="ОК",ROUNDUP(ROUND(K18/I18,10),0),"") -> 4 | P18: =IF(S18="ОК",IF(O18>0,MAX(0,K18-(O18-1)*I18),0),"") -> 5 | Q18: =IF(AND(ISNUMBER(O18),ISNUMBER($O$27),$O$27>0),O18/$O$27,0) -> 0.125 | R18: =VLOOKUP(D18,'Режимы И-ГЦ-02'!$A$8:$H$10,8,FALSE) -> 300 | S18: =IF(AND(COUNT(F18:J18)=5,F18>=0,G18>0,G18<=1,H18>0,H18<=1,I18>0,I18<=E18,J18>0,J18<=E18),"ОК","ОШИБКА: проверьте F:J") -> ОК | T18: =IF(S18<>"ОК","Исправьте ввод",IF(F18=0,"Нет в плане",IF(ABS(I18-J18)<0.000001,"Партия совпадает","НУЖЕН НОВЫЙ ХРОНОМЕТРАЖ"))) -> Партия совпадает
A19: 12 | B19: Редис | C19: Овощи и прочее | D19: 3 | E19: 3 | F19: 3 | G19: 0.98 | H19: 1 | I19: 3 | J19: 3 | K19: =IF(S19="ОК",F19/H19,"") -> 3 | L19: =IF(S19="ОК",K19/G19,"") -> 3.0612245 | M19: =IF(S19="ОК",L19-K19,"") -> 0.06122449 | N19: =IF(S19="ОК",K19-F19,"") -> 0 | O19: =IF(S19="ОК",ROUNDUP(ROUND(K19/I19,10),0),"") -> 1 | P19: =IF(S19="ОК",IF(O19>0,MAX(0,K19-(O19-1)*I19),0),"") -> 3 | Q19: =IF(AND(ISNUMBER(O19),ISNUMBER($O$27),$O$27>0),O19/$O$27,0) -> 0.03125 | R19: =VLOOKUP(D19,'Режимы И-ГЦ-02'!$A$8:$H$10,8,FALSE) -> 300 | S19: =IF(AND(COUNT(F19:J19)=5,F19>=0,G19>0,G19<=1,H19>0,H19<=1,I19>0,I19<=E19,J19>0,J19<=E19),"ОК","ОШИБКА: проверьте F:J") -> ОК | T19: =IF(S19<>"ОК","Исправьте ввод",IF(F19=0,"Нет в плане",IF(ABS(I19-J19)<0.000001,"Партия совпадает","НУЖЕН НОВЫЙ ХРОНОМЕТРАЖ"))) -> Партия совпадает
... A25: 18 | B25: Апельсин | C25: Овощи и прочее | D25: 3 | E25: 2 | F25: 2 | G25: 0.98 | H25: 1 | I25: 2 | J25: 2 | K25: =IF(S25="ОК",F25/H25,"") -> 2 | L25: =IF(S25="ОК",K25/G25,"") -> 2.0408163 | M25: =IF(S25="ОК",L25-K25,"") -> 0.040816327 | N25: =IF(S25="ОК",K25-F25,"") -> 0 | O25: =IF(S25="ОК",ROUNDUP(ROUND(K25/I25,10),0),"") -> 1 | P25: =IF(S25="ОК",IF(O25>0,MAX(0,K25-(O25-1)*I25),0),"") -> 2 | Q25: =IF(AND(ISNUMBER(O25),ISNUMBER($O$27),$O$27>0),O25/$O$27,0) -> 0.03125 | R25: =VLOOKUP(D25,'Режимы И-ГЦ-02'!$A$8:$H$10,8,FALSE) -> 300 | S25: =IF(AND(COUNT(F25:J25)=5,F25>=0,G25>0,G25<=1,H25>0,H25<=1,I25>0,I25<=E25,J25>0,J25<=E25),"ОК","ОШИБКА: проверьте F:J") -> ОК | T25: =IF(S25<>"ОК","Исправьте ввод",IF(F25=0,"Нет в плане",IF(ABS(I25-J25)<0.000001,"Партия совпадает","НУЖЕН НОВЫЙ ХРОНОМЕТРАЖ"))) -> Партия совпадает
B27: ИТОГО | F27: =IF(COUNT(F8:F25)=18,SUM(F8:F25),"") -> 107 | K27: =IF(COUNT(K8:K25)=18,SUM(K8:K25),"") -> 107 | L27: =IF(COUNT(L8:L25)=18,SUM(L8:L25),"") -> 109.57035 | M27: =IF(COUNT(M8:M25)=18,SUM(M8:M25),"") -> 2.5703545 | N27: =IF(COUNT(N8:N25)=18,SUM(N8:N25),"") -> 0 | O27: =IF(COUNT(O8:O25)=18,SUM(O8:O25),"") -> 32 | Q27: =SUM(Q8:Q25) -> 1
A29: Число партий = ROUNDUP(масса в мойку / плановая партия). Усреднение времени ведётся по количеству партий, НЕ по кг. Для неполной партии сохранены полные ручные и автоматические времена — консервативное допущение. Значение 0 в плане допустимо; пустые/ошибочные исходные данные не означают нулевой спрос.

Sheet Замеры ДО
A1: 04 / ПОЭЛЕМЕНТНЫЕ ЗАМЕРЫ · ДО · ВСЕ 18 ПРОДУКТОВ
A2: ДЕМО / ПРОЕКТ • Жёлтые ячейки — ваш ввод. Расчёты не являются утверждёнными нормативами.
A3: ← Начало | B3: Синий фон — формула; серый — инструкция; жёлтый — ввод. Защита снимается без пароля.
A5: Вводите длительность каждого элемента в секундах, НЕ накопительные отсечки. Флаг 0 исключает ВЕСЬ цикл. Если хотя бы один элемент пустой/ошибочный — весь цикл автоматически исключается.
A7: 01. Латук · ДО · 10 демонстрационных циклов, заменить реальными
A8: ="Масса замера, кг: "&'Ассортимент'!J8&". Все замеры одной партии/исполнителя/условий. Основание: "&'Ввод'!B14 -> Масса замера, кг: 1.5. Все замеры одной партии/исполнителя/условий. Основание: ДЕМО: синтетические замеры; заменить фактическими
A9: № | B9: Рабочий элемент | C9: Тип | D9: Точка отсчёта | E9: 1 | F9: 2 | G9: 3 | H9: 4 | I9: 5 | J9: 6 | K9: 7 | L9: 8 | M9: 9 | N9: 10 | O9: t min | P9: t max | Q9: Размах | R9: Рег. с | S9: t отрег. | T9: Колебания | U9: Среднее | V9: Контроль | W9: Служебно | X9: Статус
B10: Учитывать цикл: 1 / 0 | E10: 1 | F10: 1 | G10: 1 | H10: 1 | I10: 1 | J10: 1 | K10: 1 | L10: 1 | M10: 1 | N10: 1
B11: Причина исключения / условия | E11: ДЕМО | F11: ДЕМО | G11: ДЕМО | H11: ДЕМО | I11: ДЕМО | J11: ДЕМО | K11: ДЕМО | L11: ДЕМО | M11: ДЕМО | N11: ДЕМО
A12: 1 | B12: Осмотреть упаковку и сырьё | C12: Ручная | D12: Осмотр партии завершён | E12: 25 | F12: 26 | G12: 27 | H12: 25.5 | I12: 26.5 | J12: 27.5 | K12: 25.75 | L12: 26.75 | M12: 25.25 | N12: 26.25 | O12: =IF(COUNT(AG12:AP12)>0,MIN(AG12:AP12),"") -> 25 | P12: =IF(COUNT(AG12:AP12)>0,MAX(AG12:AP12),"") -> 27.5 | Q12: =IF(ISNUMBER(O12),P12-O12,"") -> 2.5 | R12: =IF(ISNUMBER(O12),IF(C12="Ручная",IF($S$24>0,$R$24*Q12/$S$24,IF($W$24=1,$R$24,0)),0),"") -> 0.91086957 | S12: =IF(ISNUMBER(O12),O12+R12,"") -> 25.91087 | T12: =IF(ISNUMBER(S12),P12-S12,"") -> 1.5891304 | U12: =IF(COUNT(AG12:AP12)>0,AVERAGE(AG12:AP12),"") -> 26.15 | AG12: =IF(ISNUMBER(E$24),E12,"") -> 25 | AH12: =IF(ISNUMBER(F$24),F12,"") -> 26 | AI12: =IF(ISNUMBER(G$24),G12,"") -> 27 | AJ12: =IF(ISNUMBER(H$24),H12,"") -> 25.5 | AK12: =IF(ISNUMBER(I$24),I12,"") -> 26.5 | AL12: =IF(ISNUMBER(J$24),J12,"") -> 27.5 | AM12: =IF(ISNUMBER(K$24),K12,"") -> 25.75 | AN12: =IF(ISNUMBER(L$24),L12,"") -> 26.75 | ... AP12: =IF(ISNUMBER(N$24),N12,"") -> 26.25 | AQ12: =IF(C12="Ручная",O12,0) -> 25
A13: 2 | B13: Отсортировать / подготовить сырьё | C13: Ручная | D13: Подготовленное сырьё отложено | E13: 102 | F13: 106 | G13: 110 | H13: 103 | I13: 107 | J13: 101 | K13: 105 | L13: 100 | M13: 104 | N13: 108 | O13: =IF(COUNT(AG13:AP13)>0,MIN(AG13:AP13),"") -> 100 | P13: =IF(COUNT(AG13:AP13)>0,MAX(AG13:AP13),"") -> 110 | Q13: =IF(ISNUMBER(O13),P13-O13,"") -> 10 | R13: =IF(ISNUMBER(O13),IF(C13="Ручная",IF($S$24>0,$R$24*Q13/$S$24,IF($W$24=2,$R$24,0)),0),"") -> 3.6434783 | S13: =IF(ISNUMBER(O13),O13+R13,"") -> 103.64348 | T13: =IF(ISNUMBER(S13),P13-S13,"") -> 6.3565217 | U13: =IF(COUNT(AG13:AP13)>0,AVERAGE(AG13:AP13),"") -> 104.6 | AG13: =IF(ISNUMBER(E$24),E13,"") -> 102 | AH13: =IF(ISNUMBER(F$24),F13,"") -> 106 | AI13: =IF(ISNUMBER(G$24),G13,"") -> 110 | AJ13: =IF(ISNUMBER(H$24),H13,"") -> 103 | AK13: =IF(ISNUMBER(I$24),I13,"") -> 107 | AL13: =IF(ISNUMBER(J$24),J13,"") -> 101 | AM13: =IF(ISNUMBER(K$24),K13,"") -> 105 | AN13: =IF(ISNUMBER(L$24),L13,"") -> 100 | ... AP13: =IF(ISNUMBER(N$24),N13,"") -> 108 | AQ13: =IF(C13="Ручная",O13,0) -> 100
A14: 3 | B14: Отвесить допустимую партию | C14: Ручная | D14: Масса партии проверена | E14: 22.66 | F14: 23.54 | G14: 22.22 | H14: 23.1 | I14: 22 | J14: 22.88 | K14: 23.76 | L14: 22.44 | M14: 23.32 | N14: 24.2 | O14: =IF(COUNT(AG14:AP14)>0,MIN(AG14:AP14),"") -> 22 | P14: =IF(COUNT(AG14:AP14)>0,MAX(AG14:AP14),"") -> 24.2 | Q14: =IF(ISNUMBER(O14),P14-O14,"") -> 2.2 | R14: =IF(ISNUMBER(O14),IF(C14="Ручная",IF($S$24>0,$R$24*Q14/$S$24,IF($W$24=3,$R$24,0)),0),"") -> 0.80156522 | S14: =IF(ISNUMBER(O14),O14+R14,"") -> 22.801565 | T14: =IF(ISNUMBER(S14),P14-S14,"") -> 1.3984348 | U14: =IF(COUNT(AG14:AP14)>0,AVERAGE(AG14:AP14),"") -> 23.012 | AG14: =IF(ISNUMBER(E$24),E14,"") -> 22.66 | AH14: =IF(ISNUMBER(F$24),F14,"") -> 23.54 | AI14: =IF(ISNUMBER(G$24),G14,"") -> 22.22 | AJ14: =IF(ISNUMBER(H$24),H14,"") -> 23.1 | AK14: =IF(ISNUMBER(I$24),I14,"") -> 22 | AL14: =IF(ISNUMBER(J$24),J14,"") -> 22.88 | AM14: =IF(ISNUMBER(K$24),K14,"") -> 23.76 | AN14: =IF(ISNUMBER(L$24),L14,"") -> 22.44 | ... AP14: =IF(ISNUMBER(N$24),N14,"") -> 24.2 | AQ14: =IF(C14="Ручная",O14,0) -> 22
A15: — | B15: Перейти с партией к SOLIA | C15: Переход | D15: Оператор у SOLIA | E15: 12.6 | F15: 12 | G15: 12.48 | H15: 12.96 | I15: 12.24 | J15: 12.72 | K15: 13.2 | L15: 12.36 | M15: 12.84 | N15: 12.12 | O15: =IF(COUNT(AG15:AP15)>0,MIN(AG15:AP15),"") -> 12 | P15: =IF(COUNT(AG15:AP15)>0,MAX(AG15:AP15),"") -> 13.2 | Q15: =IF(ISNUMBER(O15),P15-O15,"") -> 1.2 | R15: =IF(ISNUMBER(O15),IF(C15="Ручная",IF($S$24>0,$R$24*Q15/$S$24,IF($W$24=4,$R$24,0)),0),"") -> 0 | S15: =IF(ISNUMBER(O15),O15+R15,"") -> 12 | T15: =IF(ISNUMBER(S15),P15-S15,"") -> 1.2 | U15: =IF(COUNT(AG15:AP15)>0,AVERAGE(AG15:AP15),"") -> 12.552 | AG15: =IF(ISNUMBER(E$24),E15,"") -> 12.6 | AH15: =IF(ISNUMBER(F$24),F15,"") -> 12 | AI15: =IF(ISNUMBER(G$24),G15,"") -> 12.48 | AJ15: =IF(ISNUMBER(H$24),H15,"") -> 12.96 | AK15: =IF(ISNUMBER(I$24),I15,"") -> 12.24 | AL15: =IF(ISNUMBER(J$24),J15,"") -> 12.72 | AM15: =IF(ISNUMBER(K$24),K15,"") -> 13.2 | AN15: =IF(ISNUMBER(L$24),L15,"") -> 12.36 | ... AP15: =IF(ISNUMBER(N$24),N15,"") -> 12.12 | AQ15: =IF(C15="Ручная",O15,0) -> 0
A16: 5 | B16: Загрузить, выбрать программу, запустить | C16: Ручная | D16: Программа запущена | E16: 37.8 | F16: 35.7 | G16: 37.1 | H16: 38.5 | I16: 36.05 | J16: 37.45 | K16: 35.35 | L16: 36.75 | M16: 35 | N16: 36.4 | O16: =IF(COUNT(AG16:AP16)>0,MIN(AG16:AP16),"") -> 35 | P16: =IF(COUNT(AG16:AP16)>0,MAX(AG16:AP16),"") -> 38.5 | Q16: =IF(ISNUMBER(O16),P16-O16,"") -> 3.5 | R16: =IF(ISNUMBER(O16),IF(C16="Ручная",IF($S$24>0,$R$24*Q16/$S$24,IF($W$24=5,$R$24,0)),0),"") -> 1.2752174 | S16: =IF(ISNUMBER(O16),O16+R16,"") -> 36.275217 | T16: =IF(ISNUMBER(S16),P16-S16,"") -> 2.2247826 | U16: =IF(COUNT(AG16:AP16)>0,AVERAGE(AG16:AP16),"") -> 36.61 | AG16: =IF(ISNUMBER(E$24),E16,"") -> 37.8 | AH16: =IF(ISNUMBER(F$24),F16,"") -> 35.7 | AI16: =IF(ISNUMBER(G$24),G16,"") -> 37.1 | AJ16: =IF(ISNUMBER(H$24),H16,"") -> 38.5 | AK16: =IF(ISNUMBER(I$24),I16,"") -> 36.05 | AL16: =IF(ISNUMBER(J$24),J16,"") -> 37.45 | AM16: =IF(ISNUMBER(K$24),K16,"") -> 35.35 | AN16: =IF(ISNUMBER(L$24),L16,"") -> 36.75 | ... AP16: =IF(ISNUMBER(N$24),N16,"") -> 36.4 | AQ16: =IF(C16="Ручная",O16,0) -> 35
A17: — | B17: Автоматическая программа / ожидание | C17: Авто/ожидание | D17: Полный цикл программы завершён | E17: ='Ассортимент'!R8 -> 450 | F17: ='Ассортимент'!R8 -> 450 | G17: ='Ассортимент'!R8 -> 450 | H17: ='Ассортимент'!R8 -> 450 | I17: ='Ассортимент'!R8 -> 450 | J17: ='Ассортимент'!R8 -> 450 | K17: ='Ассортимент'!R8 -> 450 | L17: ='Ассортимент'!R8 -> 450 | M17: ='Ассортимент'!R8 -> 450 | N17: ='Ассортимент'!R8 -> 450 | O17: =IF(COUNT(AG17:AP17)>0,MIN(AG17:AP17),"") -> 450 | P17: =IF(COUNT(AG17:AP17)>0,MAX(AG17:AP17),"") -> 450 | Q17: =IF(ISNUMBER(O17),P17-O17,"") -> 0 | R17: =IF(ISNUMBER(O17),IF(C17="Ручная",IF($S$24>0,$R$24*Q17/$S$24,IF($W$24=6,$R$24,0)),0),"") -> 0 | S17: =IF(ISNUMBER(O17),O17+R17,"") -> 450 | T17: =IF(ISNUMBER(S17),P17-S17,"") -> 0 | U17: =IF(COUNT(AG17:AP17)>0,AVERAGE(AG17:AP17),"") -> 450 | AG17: =IF(ISNUMBER(E$24),E17,"") -> 450 | AH17: =IF(ISNUMBER(F$24),F17,"") -> 450 | AI17: =IF(ISNUMBER(G$24),G17,"") -> 450 | AJ17: =IF(ISNUMBER(H$24),H17,"") -> 450 | AK17: =IF(ISNUMBER(I$24),I17,"") -> 450 | AL17: =IF(ISNUMBER(J$24),J17,"") -> 450 | AM17: =IF(ISNUMBER(K$24),K17,"") -> 450 | AN17: =IF(ISNUMBER(L$24),L17,"") -> 450 | ... AP17: =IF(ISNUMBER(N$24),N17,"") -> 450 | AQ17: =IF(C17="Ручная",O17,0) -> 0
A18: 7 | B18: Выгрузить в чистую маркированную тару | C18: Ручная | D18: Выгрузка завершена | E18: 30.3 | F18: 31.5 | G18: 30 | H18: 31.2 | I18: 32.4 | J18: 30.6 | K18: 31.8 | L18: 33 | M18: 30.9 | N18: 32.1 | O18: =IF(COUNT(AG18:AP18)>0,MIN(AG18:AP18),"") -> 30 | P18: =IF(COUNT(AG18:AP18)>0,MAX(AG18:AP18),"") -> 33 | Q18: =IF(ISNUMBER(O18),P18-O18,"") -> 3 | R18: =IF(ISNUMBER(O18),IF(C18="Ручная",IF($S$24>0,$R$24*Q18/$S$24,IF($W$24=7,$R$24,0)),0),"") -> 1.0930435 | S18: =IF(ISNUMBER(O18),O18+R18,"") -> 31.093043 | T18: =IF(ISNUMBER(S18),P18-S18,"") -> 1.9069565 | U18: =IF(COUNT(AG18:AP18)>0,AVERAGE(AG18:AP18),"") -> 31.38 | AG18: =IF(ISNUMBER(E$24),E18,"") -> 30.3 | AH18: =IF(ISNUMBER(F$24),F18,"") -> 31.5 | AI18: =IF(ISNUMBER(G$24),G18,"") -> 30 | AJ18: =IF(ISNUMBER(H$24),H18,"") -> 31.2 | AK18: =IF(ISNUMBER(I$24),I18,"") -> 32.4 | AL18: =IF(ISNUMBER(J$24),J18,"") -> 30.6 | AM18: =IF(ISNUMBER(K$24),K18,"") -> 31.8 | AN18: =IF(ISNUMBER(L$24),L18,"") -> 33 | ... AP18: =IF(ISNUMBER(N$24),N18,"") -> 32.1 | AQ18: =IF(C18="Ручная",O18,0) -> 30
A19: 8 | B19: Проверить качество и маркировку | C19: Ручная | D19: Результат проверки подтверждён | E19: 18.72 | F19: 19.44 | G19: 18.36 | H19: 19.08 | I19: 19.8 | J19: 18.54 | K19: 19.26 | L19: 18.18 | M19: 18.9 | N19: 18 | O19: =IF(COUNT(AG19:AP19)>0,MIN(AG19:AP19),"") -> 18 | P19: =IF(COUNT(AG19:AP19)>0,MAX(AG19:AP19),"") -> 19.8 | Q19: =IF(ISNUMBER(O19),P19-O19,"") -> 1.8 | R19: =IF(ISNUMBER(O19),IF(C19="Ручная",IF($S$24>0,$R$24*Q19/$S$24,IF($W$24=8,$R$24,0)),0),"") -> 0.65582609 | S19: =IF(ISNUMBER(O19),O19+R19,"") -> 18.655826 | T19: =IF(ISNUMBER(S19),P19-S19,"") -> 1.1441739 | U19: =IF(COUNT(AG19:AP19)>0,AVERAGE(AG19:AP19),"") -> 18.828 | AG19: =IF(ISNUMBER(E$24),E19,"") -> 18.72 | AH19: =IF(ISNUMBER(F$24),F19,"") -> 19.44 | AI19: =IF(ISNUMBER(G$24),G19,"") -> 18.36 | AJ19: =IF(ISNUMBER(H$24),H19,"") -> 19.08 | AK19: =IF(ISNUMBER(I$24),I19,"") -> 19.8 | AL19: =IF(ISNUMBER(J$24),J19,"") -> 18.54 | AM19: =IF(ISNUMBER(K$24),K19,"") -> 19.26 | AN19: =IF(ISNUMBER(L$24),L19,"") -> 18.18 | ... AP19: =IF(ISNUMBER(N$24),N19,"") -> 18 | AQ19: =IF(C19="Ручная",O19,0) -> 18
A20: — | B20: Передать в зону чистой продукции | C20: Переход | D20: Партия передана | E20: 10.6 | F20: 11 | G20: 10.3 | H20: 10.7 | I20: 10.1 | J20: 10.5 | K20: 10 | L20: 10.4 | M20: 10.8 | N20: 10.2 | O20: =IF(COUNT(AG20:AP20)>0,MIN(AG20:AP20),"") -> 10 | P20: =IF(COUNT(AG20:AP20)>0,MAX(AG20:AP20),"") -> 11 | Q20: =IF(ISNUMBER(O20),P20-O20,"") -> 1 | R20: =IF(ISNUMBER(O20),IF(C20="Ручная",IF($S$24>0,$R$24*Q20/$S$24,IF($W$24=9,$R$24,0)),0),"") -> 0 | S20: =IF(ISNUMBER(O20),O20+R20,"") -> 10 | T20: =IF(ISNUMBER(S20),P20-S20,"") -> 1 | U20: =IF(COUNT(AG20:AP20)>0,AVERAGE(AG20:AP20),"") -> 10.46 | AG20: =IF(ISNUMBER(E$24),E20,"") -> 10.6 | AH20: =IF(ISNUMBER(F$24),F20,"") -> 11 | AI20: =IF(ISNUMBER(G$24),G20,"") -> 10.3 | AJ20: =IF(ISNUMBER(H$24),H20,"") -> 10.7 | AK20: =IF(ISNUMBER(I$24),I20,"") -> 10.1 | AL20: =IF(ISNUMBER(J$24),J20,"") -> 10.5 | AM20: =IF(ISNUMBER(K$24),K20,"") -> 10 | AN20: =IF(ISNUMBER(L$24),L20,"") -> 10.4 | ... AP20: =IF(ISNUMBER(N$24),N20,"") -> 10.2 | AQ20: =IF(C20="Ручная",O20,0) -> 0
A21: — | B21: Вернуться к началу цикла | C21: Переход | D21: Возврат на исходную позицию | E21: 10.7 | F21: 10.1 | G21: 10.5 | H21: 10 | I21: 10.4 | J21: 10.8 | K21: 10.2 | L21: 10.6 | M21: 11 | N21: 10.3 | O21: =IF(COUNT(AG21:AP21)>0,MIN(AG21:AP21),"") -> 10 | P21: =IF(COUNT(AG21:AP21)>0,MAX(AG21:AP21),"") -> 11 | Q21: =IF(ISNUMBER(O21),P21-O21,"") -> 1 | R21: =IF(ISNUMBER(O21),IF(C21="Ручная",IF($S$24>0,$R$24*Q21/$S$24,IF($W$24=10,$R$24,0)),0),"") -> 0 | S21: =IF(ISNUMBER(O21),O21+R21,"") -> 10 | T21: =IF(ISNUMBER(S21),P21-S21,"") -> 1 | U21: =IF(COUNT(AG21:AP21)>0,AVERAGE(AG21:AP21),"") -> 10.46 | AG21: =IF(ISNUMBER(E$24),E21,"") -> 10.7 | AH21: =IF(ISNUMBER(F$24),F21,"") -> 10.1 | AI21: =IF(ISNUMBER(G$24),G21,"") -> 10.5 | AJ21: =IF(ISNUMBER(H$24),H21,"") -> 10 | AK21: =IF(ISNUMBER(I$24),I21,"") -> 10.4 | AL21: =IF(ISNUMBER(J$24),J21,"") -> 10.8 | AM21: =IF(ISNUMBER(K$24),K21,"") -> 10.2 | AN21: =IF(ISNUMBER(L$24),L21,"") -> 10.6 | ... AP21: =IF(ISNUMBER(N$24),N21,"") -> 10.3 | AQ21: =IF(C21="Ручная",O21,0) -> 0
A22: — | B22: Внеплановый поиск тары / ожидание | C22: Потери | D22: Причина задержки устранена | E22: 12 | F22: 12.48 | G22: 12.96 | H22: 12.24 | I22: 12.72 | J22: 13.2 | K22: 12.36 | L22: 12.84 | M22: 12.12 | N22: 12.6 | O22: =IF(COUNT(AG22:AP22)>0,MIN(AG22:AP22),"") -> 12 | P22: =IF(COUNT(AG22:AP22)>0,MAX(AG22:AP22),"") -> 13.2 | Q22: =IF(ISNUMBER(O22),P22-O22,"") -> 1.2 | R22: =IF(ISNUMBER(O22),IF(C22="Ручная",IF($S$24>0,$R$24*Q22/$S$24,IF($W$24=11,$R$24,0)),0),"") -> 0 | S22: =IF(ISNUMBER(O22),O22+R22,"") -> 12 | T22: =IF(ISNUMBER(S22),P22-S22,"") -> 1.2 | U22: =IF(COUNT(AG22:AP22)>0,AVERAGE(AG22:AP22),"") -> 12.552 | AG22: =IF(ISNUMBER(E$24),E22,"") -> 12 | AH22: =IF(ISNUMBER(F$24),F22,"") -> 12.48 | AI22: =IF(ISNUMBER(G$24),G22,"") -> 12.96 | AJ22: =IF(ISNUMBER(H$24),H22,"") -> 12.24 | AK22: =IF(ISNUMBER(I$24),I22,"") -> 12.72 | AL22: =IF(ISNUMBER(J$24),J22,"") -> 13.2 | AM22: =IF(ISNUMBER(K$24),K22,"") -> 12.36 | AN22: =IF(ISNUMBER(L$24),L22,"") -> 12.84 | ... AP22: =IF(ISNUMBER(N$24),N22,"") -> 12.6 | AQ22: =IF(C22="Ручная",O22,0) -> 0
B23: ИТОГИ: все элементы цикла | E23: =IF(COUNT(E12:E22)=11,SUM(E12:E22),"") -> 732.38 | F23: =IF(COUNT(F12:F22)=11,SUM(F12:F22),"") -> 737.76 | G23: =IF(COUNT(G12:G22)=11,SUM(G12:G22),"") -> 740.92 | H23: =IF(COUNT(H12:H22)=11,SUM(H12:H22),"") -> 736.28 | I23: =IF(COUNT(I12:I22)=11,SUM(I12:I22),"") -> 739.21 | J23: =IF(COUNT(J12:J22)=11,SUM(J12:J22),"") -> 735.19 | K23: =IF(COUNT(K12:K22)=11,SUM(K12:K22),"") -> 736.68 | L23: =IF(COUNT(L12:L22)=11,SUM(L12:L22),"") -> 733.32 | ... U23: =IF(COUNT(U12:U22)=11,SUM(U12:U22),"") -> 736.604
B24: ТОЛЬКО полные учтённые циклы | E24: =IF(AND(E10=1,COUNT(E12:E22)=11,MIN(E12:E22)>=0),E23,"") -> 732.38 | F24: =IF(AND(F10=1,COUNT(F12:F22)=11,MIN(F12:F22)>=0),F23,"") -> 737.76 | G24: =IF(AND(G10=1,COUNT(G12:G22)=11,MIN(G12:G22)>=0),G23,"") -> 740.92 | H24: =IF(AND(H10=1,COUNT(H12:H22)=11,MIN(H12:H22)>=0),H23,"") -> 736.28 | I24: =IF(AND(I10=1,COUNT(I12:I22)=11,MIN(I12:I22)>=0),I23,"") -> 739.21 | J24: =IF(AND(J10=1,COUNT(J12:J22)=11,MIN(J12:J22)>=0),J23,"") -> 735.19 | K24: =IF(AND(K10=1,COUNT(K12:K22)=11,MIN(K12:K22)>=0),K23,"") -> 736.68 | L24: =IF(AND(L10=1,COUNT(L12:L22)=11,MIN(L12:L22)>=0),L23,"") -> 733.32 | ... N24: =IF(AND(N10=1,COUNT(N12:N22)=11,MIN(N12:N22)>=0),N23,"") -> 740.17 | O24: =IF(COUNT(E24:N24)>0,MIN(E24:N24),"") -> 732.38 | P24: =IF(COUNT(E24:N24)>0,MAX(E24:N24),"") -> 740.92 | Q24: =IF(ISNUMBER(O24),P24-O24,"") -> 8.54 | R24: =IF(ISNUMBER(O24),MAX(0,O24-O23),"") -> 8.38 | S24: =SUMIF(C12:C22,"Ручная",Q12:Q22) -> 23 | T24: =COUNT(E24:N24) -> 10 | U24: =IF(COUNT(E24:N24)>0,AVERAGE(E24:N24),"") -> 736.604 | V24: =IF(ISNUMBER(O24),S23-O24,"") -> 0 | W24: =MATCH(MAX(AQ12:AQ22),AQ12:AQ22,0) -> 2 | X24: =IF(T24=0,"НЕТ ЗАМЕРОВ",IF(T24<10,"МЕНЕЕ 10 ЦИКЛОВ",IF(ABS(V24)<0.000001,"ОК","ОШИБКА РЕГУЛИРОВКИ"))) -> ОК
A25: В строке учтённых циклов: O = T min; P = T max; Q = размах цикла; R = T min − сумма t min; S = сумма размахов ручных элементов; T = число циклов; U = среднее; V = сумма t отрег − T min (должно быть 0).
A28: 02. Базилик · ДО · 10 демонстрационных циклов, заменить реальными
A29: ="Масса замера, кг: "&'Ассортимент'!J9&". Все замеры одной партии/исполнителя/условий. Основание: "&'Ввод'!B14 -> Масса замера, кг: 1.5. Все замеры одной партии/исполнителя/условий. Основание: ДЕМО: синтетические замеры; заменить фактическими
A30: № | B30: Рабочий элемент | C30: Тип | D30: Точка отсчёта | E30: 1 | F30: 2 | G30: 3 | H30: 4 | I30: 5 | J30: 6 | K30: 7 | L30: 8 | M30: 9 | N30: 10 | O30: t min | P30: t max | Q30: Размах | R30: Рег. с | S30: t отрег. | T30: Колебания | U30: Среднее | V30: Контроль | W30: Служебно | X30: Статус
B31: Учитывать цикл: 1 / 0 | E31: 1 | F31: 1 | G31: 1 | H31: 1 | I31: 1 | J31: 1 | K31: 1 | L31: 1 | M31: 1 | N31: 1
B32: Причина исключения / условия | E32: ДЕМО | F32: ДЕМО | G32: ДЕМО | H32: ДЕМО | I32: ДЕМО | J32: ДЕМО | K32: ДЕМО | L32: ДЕМО | M32: ДЕМО | N32: ДЕМО
A33: 1 | B33: Осмотреть упаковку и сырьё | C33: Ручная | D33: Осмотр партии завершён | E33: 26 | F33: 27 | G33: 25.5 | H33: 26.5 | I33: 27.5 | J33: 25.75 | K33: 26.75 | L33: 25.25 | M33: 26.25 | N33: 25 | O33: =IF(COUNT(AG33:AP33)>0,MIN(AG33:AP33),"") -> 25 | P33: =IF(COUNT(AG33:AP33)>0,MAX(AG33:AP33),"") -> 27.5 | Q33: =IF(ISNUMBER(O33),P33-O33,"") -> 2.5 | R33: =IF(ISNUMBER(O33),IF(C33="Ручная",IF($S$45>0,$R$45*Q33/$S$45,IF($W$45=1,$R$45,0)),0),"") -> 0.89375 | S33: =IF(ISNUMBER(O33),O33+R33,"") -> 25.89375 | T33: =IF(ISNUMBER(S33),P33-S33,"") -> 1.60625 | U33: =IF(COUNT(AG33:AP33)>0,AVERAGE(AG33:AP33),"") -> 26.15 | AG33: =IF(ISNUMBER(E$45),E33,"") -> 26 | AH33: =IF(ISNUMBER(F$45),F33,"") -> 27 | AI33: =IF(ISNUMBER(G$45),G33,"") -> 25.5 | AJ33: =IF(ISNUMBER(H$45),H33,"") -> 26.5 | AK33: =IF(ISNUMBER(I$45),I33,"") -> 27.5 | AL33: =IF(ISNUMBER(J$45),J33,"") -> 25.75 | AM33: =IF(ISNUMBER(K$45),K33,"") -> 26.75 | AN33: =IF(ISNUMBER(L$45),L33,"") -> 25.25 | ... AP33: =IF(ISNUMBER(N$45),N33,"") -> 25 | AQ33: =IF(C33="Ручная",O33,0) -> 25
A34: 2 | B34: Отсортировать / подготовить сырьё | C34: Ручная | D34: Подготовленное сырьё отложено | E34: 116.6 | F34: 121 | G34: 113.3 | H34: 117.7 | I34: 111.1 | J34: 115.5 | K34: 110 | L34: 114.4 | M34: 118.8 | N34: 112.2 | O34: =IF(COUNT(AG34:AP34)>0,MIN(AG34:AP34),"") -> 110 | P34: =IF(COUNT(AG34:AP34)>0,MAX(AG34:AP34),"") -> 121 | Q34: =IF(ISNUMBER(O34),P34-O34,"") -> 11 | R34: =IF(ISNUMBER(O34),IF(C34="Ручная",IF($S$45>0,$R$45*Q34/$S$45,IF($W$45=2,$R$45,0)),0),"") -> 3.9325 | S34: =IF(ISNUMBER(O34),O34+R34,"") -> 113.9325 | T34: =IF(ISNUMBER(S34),P34-S34,"") -> 7.0675 | U34: =IF(COUNT(AG34:AP34)>0,AVERAGE(AG34:AP34),"") -> 115.06 | AG34: =IF(ISNUMBER(E$45),E34,"") -> 116.6 | AH34: =IF(ISNUMBER(F$45),F34,"") -> 121 | AI34: =IF(ISNUMBER(G$45),G34,"") -> 113.3 | AJ34: =IF(ISNUMBER(H$45),H34,"") -> 117.7 | AK34: =IF(ISNUMBER(I$45),I34,"") -> 111.1 | AL34: =IF(ISNUMBER(J$45),J34,"") -> 115.5 | AM34: =IF(ISNUMBER(K$45),K34,"") -> 110 | AN34: =IF(ISNUMBER(L$45),L34,"") -> 114.4 | ... AP34: =IF(ISNUMBER(N$45),N34,"") -> 112.2 | AQ34: =IF(C34="Ручная",O34,0) -> 110
A35: 3 | B35: Отвесить допустимую партию | C35: Ручная | D35: Масса партии проверена | E35: 23.54 | F35: 22.22 | G35: 23.1 | H35: 22 | I35: 22.88 | J35: 23.76 | K35: 22.44 | L35: 23.32 | M35: 24.2 | N35: 22.66 | O35: =IF(COUNT(AG35:AP35)>0,MIN(AG35:AP35),"") -> 22 | P35: =IF(COUNT(AG35:AP35)>0,MAX(AG35:AP35),"") -> 24.2 | Q35: =IF(ISNUMBER(O35),P35-O35,"") -> 2.2 | R35: =IF(ISNUMBER(O35),IF(C35="Ручная",IF($S$45>0,$R$45*Q35/$S$45,IF($W$45=3,$R$45,0)),0),"") -> 0.7865 | S35: =IF(ISNUMBER(O35),O35+R35,"") -> 22.7865 | T35: =IF(ISNUMBER(S35),P35-S35,"") -> 1.4135 | U35: =IF(COUNT(AG35:AP35)>0,AVERAGE(AG35:AP35),"") -> 23.012 | AG35: =IF(ISNUMBER(E$45),E35,"") -> 23.54 | AH35: =IF(ISNUMBER(F$45),F35,"") -> 22.22 | AI35: =IF(ISNUMBER(G$45),G35,"") -> 23.1 | AJ35: =IF(ISNUMBER(H$45),H35,"") -> 22 | AK35: =IF(ISNUMBER(I$45),I35,"") -> 22.88 | AL35: =IF(ISNUMBER(J$45),J35,"") -> 23.76 | AM35: =IF(ISNUMBER(K$45),K35,"") -> 22.44 | AN35: =IF(ISNUMBER(L$45),L35,"") -> 23.32 | ... AP35: =IF(ISNUMBER(N$45),N35,"") -> 22.66 | AQ35: =IF(C35="Ручная",O35,0) -> 22
A36: — | B36: Перейти с партией к SOLIA | C36: Переход | D36: Оператор у SOLIA | E36: 12 | F36: 12.48 | G36: 12.96 | H36: 12.24 | I36: 12.72 | J36: 13.2 | K36: 12.36 | L36: 12.84 | M36: 12.12 | N36: 12.6 | O36: =IF(COUNT(AG36:AP36)>0,MIN(AG36:AP36),"") -> 12 | P36: =IF(COUNT(AG36:AP36)>0,MAX(AG36:AP36),"") -> 13.2 | Q36: =IF(ISNUMBER(O36),P36-O36,"") -> 1.2 | R36: =IF(ISNUMBER(O36),IF(C36="Ручная",IF($S$45>0,$R$45*Q36/$S$45,IF($W$45=4,$R$45,0)),0),"") -> 0 | S36: =IF(ISNUMBER(O36),O36+R36,"") -> 12 | T36: =IF(ISNUMBER(S36),P36-S36,"") -> 1.2 | U36: =IF(COUNT(AG36:AP36)>0,AVERAGE(AG36:AP36),"") -> 12.552 | AG36: =IF(ISNUMBER(E$45),E36,"") -> 12 | AH36: =IF(ISNUMBER(F$45),F36,"") -> 12.48 | AI36: =IF(ISNUMBER(G$45),G36,"") -> 12.96 | AJ36: =IF(ISNUMBER(H$45),H36,"") -> 12.24 | AK36: =IF(ISNUMBER(I$45),I36,"") -> 12.72 | AL36: =IF(ISNUMBER(J$45),J36,"") -> 13.2 | AM36: =IF(ISNUMBER(K$45),K36,"") -> 12.36 | AN36: =IF(ISNUMBER(L$45),L36,"") -> 12.84 | ... AP36: =IF(ISNUMBER(N$45),N36,"") -> 12.6 | AQ36: =IF(C36="Ручная",O36,0) -> 0
A37: 5 | B37: Загрузить, выбрать программу, запустить | C37: Ручная | D37: Программа запущена | E37: 35.7 | F37: 37.1 | G37: 38.5 | H37: 36.05 | I37: 37.45 | J37: 35.35 | K37: 36.75 | L37: 35 | M37: 36.4 | N37: 37.8 | O37: =IF(COUNT(AG37:AP37)>0,MIN(AG37:AP37),"") -> 35 | P37: =IF(COUNT(AG37:AP37)>0,MAX(AG37:AP37),"") -> 38.5 | Q37: =IF(ISNUMBER(O37),P37-O37,"") -> 3.5 | R37: =IF(ISNUMBER(O37),IF(C37="Ручная",IF($S$45>0,$R$45*Q37/$S$45,IF($W$45=5,$R$45,0)),0),"") -> 1.25125 | S37: =IF(ISNUMBER(O37),O37+R37,"") -> 36.25125 | T37: =IF(ISNUMBER(S37),P37-S37,"") -> 2.24875 | U37: =IF(COUNT(AG37:AP37)>0,AVERAGE(AG37:AP37),"") -> 36.61 | AG37: =IF(ISNUMBER(E$45),E37,"") -> 35.7 | AH37: =IF(ISNUMBER(F$45),F37,"") -> 37.1 | AI37: =IF(ISNUMBER(G$45),G37,"") -> 38.5 | AJ37: =IF(ISNUMBER(H$45),H37,"") -> 36.05 | AK37: =IF(ISNUMBER(I$45),I37,"") -> 37.45 | AL37: =IF(ISNUMBER(J$45),J37,"") -> 35.35 | AM37: =IF(ISNUMBER(K$45),K37,"") -> 36.75 | AN37: =IF(ISNUMBER(L$45),L37,"") -> 35 | ... AP37: =IF(ISNUMBER(N$45),N37,"") -> 37.8 | AQ37: =IF(C37="Ручная",O37,0) -> 35
A38: — | B38: Автоматическая программа / ожидание | C38: Авто/ожидание | D38: Полный цикл программы завершён | E38: ='Ассортимент'!R9 -> 450 | F38: ='Ассортимент'!R9 -> 450 | G38: ='Ассортимент'!R9 -> 450 | H38: ='Ассортимент'!R9 -> 450 | I38: ='Ассортимент'!R9 -> 450 | J38: ='Ассортимент'!R9 -> 450 | K38: ='Ассортимент'!R9 -> 450 | L38: ='Ассортимент'!R9 -> 450 | M38: ='Ассортимент'!R9 -> 450 | N38: ='Ассортимент'!R9 -> 450 | O38: =IF(COUNT(AG38:AP38)>0,MIN(AG38:AP38),"") -> 450 | P38: =IF(COUNT(AG38:AP38)>0,MAX(AG38:AP38),"") -> 450 | Q38: =IF(ISNUMBER(O38),P38-O38,"") -> 0 | R38: =IF(ISNUMBER(O38),IF(C38="Ручная",IF($S$45>0,$R$45*Q38/$S$45,IF($W$45=6,$R$45,0)),0),"") -> 0 | S38: =IF(ISNUMBER(O38),O38+R38,"") -> 450 | T38: =IF(ISNUMBER(S38),P38-S38,"") -> 0 | U38: =IF(COUNT(AG38:AP38)>0,AVERAGE(AG38:AP38),"") -> 450 | AG38: =IF(ISNUMBER(E$45),E38,"") -> 450 | AH38: =IF(ISNUMBER(F$45),F38,"") -> 450 | AI38: =IF(ISNUMBER(G$45),G38,"") -> 450 | AJ38: =IF(ISNUMBER(H$45),H38,"") -> 450 | AK38: =IF(ISNUMBER(I$45),I38,"") -> 450 | AL38: =IF(ISNUMBER(J$45),J38,"") -> 450 | AM38: =IF(ISNUMBER(K$45),K38,"") -> 450 | AN38: =IF(ISNUMBER(L$45),L38,"") -> 450 | ... AP38: =IF(ISNUMBER(N$45),N38,"") -> 450 | AQ38: =IF(C38="Ручная",O38,0) -> 0
A39: 7 | B39: Выгрузить в чистую маркированную тару | C39: Ручная | D39: Выгрузка завершена | E39: 31.5 | F39: 30 | G39: 31.2 | H39: 32.4 | I39: 30.6 | J39: 31.8 | K39: 33 | L39: 30.9 | M39: 32.1 | N39: 30.3 | O39: =IF(COUNT(AG39:AP39)>0,MIN(AG39:AP39),"") -> 30 | P39: =IF(COUNT(AG39:AP39)>0,MAX(AG39:AP39),"") -> 33 | Q39: =IF(ISNUMBER(O39),P39-O39,"") -> 3 | R39: =IF(ISNUMBER(O39),IF(C39="Ручная",IF($S$45>0,$R$45*Q39/$S$45,IF($W$45=7,$R$45,0)),0),"") -> 1.0725 | S39: =IF(ISNUMBER(O39),O39+R39,"") -> 31.0725 | T39: =IF(ISNUMBER(S39),P39-S39,"") -> 1.9275 | U39: =IF(COUNT(AG39:AP39)>0,AVERAGE(AG39:AP39),"") -> 31.38 | AG39: =IF(ISNUMBER(E$45),E39,"") -> 31.5 | AH39: =IF(ISNUMBER(F$45),F39,"") -> 30 | AI39: =IF(ISNUMBER(G$45),G39,"") -> 31.2 | AJ39: =IF(ISNUMBER(H$45),H39,"") -> 32.4 | AK39: =IF(ISNUMBER(I$45),I39,"") -> 30.6 | AL39: =IF(ISNUMBER(J$45),J39,"") -> 31.8 | AM39: =IF(ISNUMBER(K$45),K39,"") -> 33 | AN39: =IF(ISNUMBER(L$45),L39,"") -> 30.9 | ... AP39: =IF(ISNUMBER(N$45),N39,"") -> 30.3 | AQ39: =IF(C39="Ручная",O39,0) -> 30
A40: 8 | B40: Проверить качество и маркировку | C40: Ручная | D40: Результат проверки подтверждён | E40: 19.44 | F40: 18.36 | G40: 19.08 | H40: 19.8 | I40: 18.54 | J40: 19.26 | K40: 18.18 | L40: 18.9 | M40: 18 | N40: 18.72 | O40: =IF(COUNT(AG40:AP40)>0,MIN(AG40:AP40),"") -> 18 | P40: =IF(COUNT(AG40:AP40)>0,MAX(AG40:AP40),"") -> 19.8 | Q40: =IF(ISNUMBER(O40),P40-O40,"") -> 1.8 | R40: =IF(ISNUMBER(O40),IF(C40="Ручная",IF($S$45>0,$R$45*Q40/$S$45,IF($W$45=8,$R$45,0)),0),"") -> 0.6435 | S40: =IF(ISNUMBER(O40),O40+R40,"") -> 18.6435 | T40: =IF(ISNUMBER(S40),P40-S40,"") -> 1.1565 | U40: =IF(COUNT(AG40:AP40)>0,AVERAGE(AG40:AP40),"") -> 18.828 | AG40: =IF(ISNUMBER(E$45),E40,"") -> 19.44 | AH40: =IF(ISNUMBER(F$45),F40,"") -> 18.36 | AI40: =IF(ISNUMBER(G$45),G40,"") -> 19.08 | AJ40: =IF(ISNUMBER(H$45),H40,"") -> 19.8 | AK40: =IF(ISNUMBER(I$45),I40,"") -> 18.54 | AL40: =IF(ISNUMBER(J$45),J40,"") -> 19.26 | AM40: =IF(ISNUMBER(K$45),K40,"") -> 18.18 | AN40: =IF(ISNUMBER(L$45),L40,"") -> 18.9 | ... AP40: =IF(ISNUMBER(N$45),N40,"") -> 18.72 | AQ40: =IF(C40="Ручная",O40,0) -> 18
A41: — | B41: Передать в зону чистой продукции | C41: Переход | D41: Партия передана | E41: 11 | F41: 10.3 | G41: 10.7 | H41: 10.1 | I41: 10.5 | J41: 10 | K41: 10.4 | L41: 10.8 | M41: 10.2 | N41: 10.6 | O41: =IF(COUNT(AG41:AP41)>0,MIN(AG41:AP41),"") -> 10 | P41: =IF(COUNT(AG41:AP41)>0,MAX(AG41:AP41),"") -> 11 | Q41: =IF(ISNUMBER(O41),P41-O41,"") -> 1 | R41: =IF(ISNUMBER(O41),IF(C41="Ручная",IF($S$45>0,$R$45*Q41/$S$45,IF($W$45=9,$R$45,0)),0),"") -> 0 | S41: =IF(ISNUMBER(O41),O41+R41,"") -> 10 | T41: =IF(ISNUMBER(S41),P41-S41,"") -> 1 | U41: =IF(COUNT(AG41:AP41)>0,AVERAGE(AG41:AP41),"") -> 10.46 | AG41: =IF(ISNUMBER(E$45),E41,"") -> 11 | AH41: =IF(ISNUMBER(F$45),F41,"") -> 10.3 | AI41: =IF(ISNUMBER(G$45),G41,"") -> 10.7 | AJ41: =IF(ISNUMBER(H$45),H41,"") -> 10.1 | AK41: =IF(ISNUMBER(I$45),I41,"") -> 10.5 | AL41: =IF(ISNUMBER(J$45),J41,"") -> 10 | AM41: =IF(ISNUMBER(K$45),K41,"") -> 10.4 | AN41: =IF(ISNUMBER(L$45),L41,"") -> 10.8 | ... AP41: =IF(ISNUMBER(N$45),N41,"") -> 10.6 | AQ41: =IF(C41="Ручная",O41,0) -> 0
A42: — | B42: Вернуться к началу цикла | C42: Переход | D42: Возврат на исходную позицию | E42: 10.1 | F42: 10.5 | G42: 10 | H42: 10.4 | I42: 10.8 | J42: 10.2 | K42: 10.6 | L42: 11 | M42: 10.3 | N42: 10.7 | O42: =IF(COUNT(AG42:AP42)>0,MIN(AG42:AP42),"") -> 10 | P42: =IF(COUNT(AG42:AP42)>0,MAX(AG42:AP42),"") -> 11 | Q42: =IF(ISNUMBER(O42),P42-O42,"") -> 1 | R42: =IF(ISNUMBER(O42),IF(C42="Ручная",IF($S$45>0,$R$45*Q42/$S$45,IF($W$45=10,$R$45,0)),0),"") -> 0 | S42: =IF(ISNUMBER(O42),O42+R42,"") -> 10 | T42: =IF(ISNUMBER(S42),P42-S42,"") -> 1 | U42: =IF(COUNT(AG42:AP42)>0,AVERAGE(AG42:AP42),"") -> 10.46 | AG42: =IF(ISNUMBER(E$45),E42,"") -> 10.1 | AH42: =IF(ISNUMBER(F$45),F42,"") -> 10.5 | AI42: =IF(ISNUMBER(G$45),G42,"") -> 10 | AJ42: =IF(ISNUMBER(H$45),H42,"") -> 10.4 | AK42: =IF(ISNUMBER(I$45),I42,"") -> 10.8 | AL42: =IF(ISNUMBER(J$45),J42,"") -> 10.2 | AM42: =IF(ISNUMBER(K$45),K42,"") -> 10.6 | AN42: =IF(ISNUMBER(L$45),L42,"") -> 11 | ... AP42: =IF(ISNUMBER(N$45),N42,"") -> 10.7 | AQ42: =IF(C42="Ручная",O42,0) -> 0
A43: — | B43: Внеплановый поиск тары / ожидание | C43: Потери | D43: Причина задержки устранена | E43: 12.48 | F43: 12.96 | G43: 12.24 | H43: 12.72 | I43: 13.2 | J43: 12.36 | K43: 12.84 | L43: 12.12 | M43: 12.6 | N43: 12 | O43: =IF(COUNT(AG43:AP43)>0,MIN(AG43:AP43),"") -> 12 | P43: =IF(COUNT(AG43:AP43)>0,MAX(AG43:AP43),"") -> 13.2 | Q43: =IF(ISNUMBER(O43),P43-O43,"") -> 1.2 | R43: =IF(ISNUMBER(O43),IF(C43="Ручная",IF($S$45>0,$R$45*Q43/$S$45,IF($W$45=11,$R$45,0)),0),"") -> 0 | S43: =IF(ISNUMBER(O43),O43+R43,"") -> 12 | T43: =IF(ISNUMBER(S43),P43-S43,"") -> 1.2 | U43: =IF(COUNT(AG43:AP43)>0,AVERAGE(AG43:AP43),"") -> 12.552 | AG43: =IF(ISNUMBER(E$45),E43,"") -> 12.48 | AH43: =IF(ISNUMBER(F$45),F43,"") -> 12.96 | AI43: =IF(ISNUMBER(G$45),G43,"") -> 12.24 | AJ43: =IF(ISNUMBER(H$45),H43,"") -> 12.72 | AK43: =IF(ISNUMBER(I$45),I43,"") -> 13.2 | AL43: =IF(ISNUMBER(J$45),J43,"") -> 12.36 | AM43: =IF(ISNUMBER(K$45),K43,"") -> 12.84 | AN43: =IF(ISNUMBER(L$45),L43,"") -> 12.12 | ... AP43: =IF(ISNUMBER(N$45),N43,"") -> 12 | AQ43: =IF(C43="Ручная",O43,0) -> 0
B44: ИТОГИ: все элементы цикла | E44: =IF(COUNT(E33:E43)=11,SUM(E33:E43),"") -> 748.36 | F44: =IF(COUNT(F33:F43)=11,SUM(F33:F43),"") -> 751.92 | G44: =IF(COUNT(G33:G43)=11,SUM(G33:G43),"") -> 746.58 | H44: =IF(COUNT(H33:H43)=11,SUM(H33:H43),"") -> 749.91 | I44: =IF(COUNT(I33:I43)=11,SUM(I33:I43),"") -> 745.29 | J44: =IF(COUNT(J33:J43)=11,SUM(J33:J43),"") -> 747.18 | K44: =IF(COUNT(K33:K43)=11,SUM(K33:K43),"") -> 743.32 | L44: =IF(COUNT(L33:L43)=11,SUM(L33:L43),"") -> 744.53 | ... U44: =IF(COUNT(U33:U43)=11,SUM(U33:U43),"") -> 747.064
...

Sheet Замеры ЦЕЛЬ
A1: 04 / ПОЭЛЕМЕНТНЫЕ ЗАМЕРЫ · ЦЕЛЬ · ВСЕ 18 ПРОДУКТОВ
A2: ДЕМО / ПРОЕКТ • Жёлтые ячейки — ваш ввод. Расчёты не являются утверждёнными нормативами.
A3: ← Начало | B3: Синий фон — формула; серый — инструкция; жёлтый — ввод. Защита снимается без пароля.
A5: Вводите длительность каждого элемента в секундах, НЕ накопительные отсечки. Флаг 0 исключает ВЕСЬ цикл. Если хотя бы один элемент пустой/ошибочный — весь цикл автоматически исключается.
A7: 01. Латук · ЦЕЛЬ · 10 демонстрационных циклов, заменить реальными
A8: ="Масса замера, кг: "&'Ассортимент'!J8&". Все замеры одной партии/исполнителя/условий. Основание: "&'Ввод'!B15 -> Масса замера, кг: 1.5. Все замеры одной партии/исполнителя/условий. Основание: ДЕМО: прогноз; улучшения не внедрены
A9: № | B9: Рабочий элемент | C9: Тип | D9: Точка отсчёта | E9: 1 | F9: 2 | G9: 3 | H9: 4 | I9: 5 | J9: 6 | K9: 7 | L9: 8 | M9: 9 | N9: 10 | O9: t min | P9: t max | Q9: Размах | R9: Рег. с | S9: t отрег. | T9: Колебания | U9: Среднее | V9: Контроль | W9: Служебно | X9: Статус
B10: Учитывать цикл: 1 / 0 | E10: 1 | F10: 1 | G10: 1 | H10: 1 | I10: 1 | J10: 1 | K10: 1 | L10: 1 | M10: 1 | N10: 1
B11: Причина исключения / условия | E11: ДЕМО | F11: ДЕМО | G11: ДЕМО | H11: ДЕМО | I11: ДЕМО | J11: ДЕМО | K11: ДЕМО | L11: ДЕМО | M11: ДЕМО | N11: ДЕМО
A12: 1 | B12: Осмотреть упаковку и сырьё | C12: Ручная | D12: Осмотр партии завершён | E12: 25 | F12: 26 | G12: 27 | H12: 25.5 | I12: 26.5 | J12: 27.5 | K12: 25.75 | L12: 26.75 | M12: 25.25 | N12: 26.25 | O12: =IF(COUNT(AG12:AP12)>0,MIN(AG12:AP12),"") -> 25 | P12: =IF(COUNT(AG12:AP12)>0,MAX(AG12:AP12),"") -> 27.5 | Q12: =IF(ISNUMBER(O12),P12-O12,"") -> 2.5 | R12: =IF(ISNUMBER(O12),IF(C12="Ручная",IF($S$24>0,$R$24*Q12/$S$24,IF($W$24=1,$R$24,0)),0),"") -> 0.78665756 | S12: =IF(ISNUMBER(O12),O12+R12,"") -> 25.786658 | T12: =IF(ISNUMBER(S12),P12-S12,"") -> 1.7133424 | U12: =IF(COUNT(AG12:AP12)>0,AVERAGE(AG12:AP12),"") -> 26.15 | AG12: =IF(ISNUMBER(E$24),E12,"") -> 25 | AH12: =IF(ISNUMBER(F$24),F12,"") -> 26 | AI12: =IF(ISNUMBER(G$24),G12,"") -> 27 | AJ12: =IF(ISNUMBER(H$24),H12,"") -> 25.5 | AK12: =IF(ISNUMBER(I$24),I12,"") -> 26.5 | AL12: =IF(ISNUMBER(J$24),J12,"") -> 27.5 | AM12: =IF(ISNUMBER(K$24),K12,"") -> 25.75 | AN12: =IF(ISNUMBER(L$24),L12,"") -> 26.75 | ... AP12: =IF(ISNUMBER(N$24),N12,"") -> 26.25 | AQ12: =IF(C12="Ручная",O12,0) -> 25
A13: 2 | B13: Отсортировать / подготовить сырьё | C13: Ручная | D13: Подготовленное сырьё отложено | E13: 102 | F13: 106 | G13: 110 | H13: 103 | I13: 107 | J13: 101 | K13: 105 | L13: 100 | M13: 104 | N13: 108 | O13: =IF(COUNT(AG13:AP13)>0,MIN(AG13:AP13),"") -> 100 | P13: =IF(COUNT(AG13:AP13)>0,MAX(AG13:AP13),"") -> 110 | Q13: =IF(ISNUMBER(O13),P13-O13,"") -> 10 | R13: =IF(ISNUMBER(O13),IF(C13="Ручная",IF($S$24>0,$R$24*Q13/$S$24,IF($W$24=2,$R$24,0)),0),"") -> 3.1466302 | S13: =IF(ISNUMBER(O13),O13+R13,"") -> 103.14663 | T13: =IF(ISNUMBER(S13),P13-S13,"") -> 6.8533698 | U13: =IF(COUNT(AG13:AP13)>0,AVERAGE(AG13:AP13),"") -> 104.6 | AG13: =IF(ISNUMBER(E$24),E13,"") -> 102 | AH13: =IF(ISNUMBER(F$24),F13,"") -> 106 | AI13: =IF(ISNUMBER(G$24),G13,"") -> 110 | AJ13: =IF(ISNUMBER(H$24),H13,"") -> 103 | AK13: =IF(ISNUMBER(I$24),I13,"") -> 107 | AL13: =IF(ISNUMBER(J$24),J13,"") -> 101 | AM13: =IF(ISNUMBER(K$24),K13,"") -> 105 | AN13: =IF(ISNUMBER(L$24),L13,"") -> 100 | ... AP13: =IF(ISNUMBER(N$24),N13,"") -> 108 | AQ13: =IF(C13="Ручная",O13,0) -> 100
A14: 3 | B14: Отвесить допустимую партию | C14: Ручная | D14: Масса партии проверена | E14: 20.39 | F14: 21.19 | G14: 20 | H14: 20.79 | I14: 19.8 | J14: 20.59 | K14: 21.38 | L14: 20.2 | M14: 20.99 | N14: 21.78 | O14: =IF(COUNT(AG14:AP14)>0,MIN(AG14:AP14),"") -> 19.8 | P14: =IF(COUNT(AG14:AP14)>0,MAX(AG14:AP14),"") -> 21.78 | Q14: =IF(ISNUMBER(O14),P14-O14,"") -> 1.98 | R14: =IF(ISNUMBER(O14),IF(C14="Ручная",IF($S$24>0,$R$24*Q14/$S$24,IF($W$24=3,$R$24,0)),0),"") -> 0.62303279 | S14: =IF(ISNUMBER(O14),O14+R14,"") -> 20.423033 | T14: =IF(ISNUMBER(S14),P14-S14,"") -> 1.3569672 | U14: =IF(COUNT(AG14:AP14)>0,AVERAGE(AG14:AP14),"") -> 20.711 | AG14: =IF(ISNUMBER(E$24),E14,"") -> 20.39 | AH14: =IF(ISNUMBER(F$24),F14,"") -> 21.19 | AI14: =IF(ISNUMBER(G$24),G14,"") -> 20 | AJ14: =IF(ISNUMBER(H$24),H14,"") -> 20.79 | AK14: =IF(ISNUMBER(I$24),I14,"") -> 19.8 | AL14: =IF(ISNUMBER(J$24),J14,"") -> 20.59 | AM14: =IF(ISNUMBER(K$24),K14,"") -> 21.38 | AN14: =IF(ISNUMBER(L$24),L14,"") -> 20.2 | ... AP14: =IF(ISNUMBER(N$24),N14,"") -> 21.78 | AQ14: =IF(C14="Ручная",O14,0) -> 19.8
A15: — | B15: Перейти с партией к SOLIA | C15: Переход | D15: Оператор у SOLIA | E15: 6.3 | F15: 6 | G15: 6.24 | H15: 6.48 | I15: 6.12 | J15: 6.36 | K15: 6.6 | L15: 6.18 | M15: 6.42 | N15: 6.06 | O15: =IF(COUNT(AG15:AP15)>0,MIN(AG15:AP15),"") -> 6 | P15: =IF(COUNT(AG15:AP15)>0,MAX(AG15:AP15),"") -> 6.6 | Q15: =IF(ISNUMBER(O15),P15-O15,"") -> 0.6 | R15: =IF(ISNUMBER(O15),IF(C15="Ручная",IF($S$24>0,$R$24*Q15/$S$24,IF($W$24=4,$R$24,0)),0),"") -> 0 | S15: =IF(ISNUMBER(O15),O15+R15,"") -> 6 | T15: =IF(ISNUMBER(S15),P15-S15,"") -> 0.6 | U15: =IF(COUNT(AG15:AP15)>0,AVERAGE(AG15:AP15),"") -> 6.276 | AG15: =IF(ISNUMBER(E$24),E15,"") -> 6.3 | AH15: =IF(ISNUMBER(F$24),F15,"") -> 6 | AI15: =IF(ISNUMBER(G$24),G15,"") -> 6.24 | AJ15: =IF(ISNUMBER(H$24),H15,"") -> 6.48 | AK15: =IF(ISNUMBER(I$24),I15,"") -> 6.12 | AL15: =IF(ISNUMBER(J$24),J15,"") -> 6.36 | AM15: =IF(ISNUMBER(K$24),K15,"") -> 6.6 | AN15: =IF(ISNUMBER(L$24),L15,"") -> 6.18 | ... AP15: =IF(ISNUMBER(N$24),N15,"") -> 6.06 | AQ15: =IF(C15="Ручная",O15,0) -> 0
A16: 5 | B16: Загрузить, выбрать программу, запустить | C16: Ручная | D16: Программа запущена | E16: 32.13 | F16: 30.34 | G16: 31.54 | H16: 32.73 | I16: 30.64 | J16: 31.83 | K16: 30.05 | L16: 31.24 | M16: 29.75 | N16: 30.94 | O16: =IF(COUNT(AG16:AP16)>0,MIN(AG16:AP16),"") -> 29.75 | P16: =IF(COUNT(AG16:AP16)>0,MAX(AG16:AP16),"") -> 32.73 | Q16: =IF(ISNUMBER(O16),P16-O16,"") -> 2.98 | R16: =IF(ISNUMBER(O16),IF(C16="Ручная",IF($S$24>0,$R$24*Q16/$S$24,IF($W$24=5,$R$24,0)),0),"") -> 0.93769581 | S16: =IF(ISNUMBER(O16),O16+R16,"") -> 30.687696 | T16: =IF(ISNUMBER(S16),P16-S16,"") -> 2.0423042 | U16: =IF(COUNT(AG16:AP16)>0,AVERAGE(AG16:AP16),"") -> 31.119 | AG16: =IF(ISNUMBER(E$24),E16,"") -> 32.13 | AH16: =IF(ISNUMBER(F$24),F16,"") -> 30.34 | AI16: =IF(ISNUMBER(G$24),G16,"") -> 31.54 | AJ16: =IF(ISNUMBER(H$24),H16,"") -> 32.73 | AK16: =IF(ISNUMBER(I$24),I16,"") -> 30.64 | AL16: =IF(ISNUMBER(J$24),J16,"") -> 31.83 | AM16: =IF(ISNUMBER(K$24),K16,"") -> 30.05 | AN16: =IF(ISNUMBER(L$24),L16,"") -> 31.24 | ... AP16: =IF(ISNUMBER(N$24),N16,"") -> 30.94 | AQ16: =IF(C16="Ручная",O16,0) -> 29.75
A17: — | B17: Автоматическая программа / ожидание | C17: Авто/ожидание | D17: Полный цикл программы завершён | E17: ='Ассортимент'!R8 -> 450 | F17: ='Ассортимент'!R8 -> 450 | G17: ='Ассортимент'!R8 -> 450 | H17: ='Ассортимент'!R8 -> 450 | I17: ='Ассортимент'!R8 -> 450 | J17: ='Ассортимент'!R8 -> 450 | K17: ='Ассортимент'!R8 -> 450 | L17: ='Ассортимент'!R8 -> 450 | M17: ='Ассортимент'!R8 -> 450 | N17: ='Ассортимент'!R8 -> 450 | O17: =IF(COUNT(AG17:AP17)>0,MIN(AG17:AP17),"") -> 450 | P17: =IF(COUNT(AG17:AP17)>0,MAX(AG17:AP17),"") -> 450 | Q17: =IF(ISNUMBER(O17),P17-O17,"") -> 0 | R17: =IF(ISNUMBER(O17),IF(C17="Ручная",IF($S$24>0,$R$24*Q17/$S$24,IF($W$24=6,$R$24,0)),0),"") -> 0 | S17: =IF(ISNUMBER(O17),O17+R17,"") -> 450 | T17: =IF(ISNUMBER(S17),P17-S17,"") -> 0 | U17: =IF(COUNT(AG17:AP17)>0,AVERAGE(AG17:AP17),"") -> 450 | AG17: =IF(ISNUMBER(E$24),E17,"") -> 450 | AH17: =IF(ISNUMBER(F$24),F17,"") -> 450 | AI17: =IF(ISNUMBER(G$24),G17,"") -> 450 | AJ17: =IF(ISNUMBER(H$24),H17,"") -> 450 | AK17: =IF(ISNUMBER(I$24),I17,"") -> 450 | AL17: =IF(ISNUMBER(J$24),J17,"") -> 450 | AM17: =IF(ISNUMBER(K$24),K17,"") -> 450 | AN17: =IF(ISNUMBER(L$24),L17,"") -> 450 | ... AP17: =IF(ISNUMBER(N$24),N17,"") -> 450 | AQ17: =IF(C17="Ручная",O17,0) -> 0
A18: 7 | B18: Выгрузить в чистую маркированную тару | C18: Ручная | D18: Выгрузка завершена | E18: 27.27 | F18: 28.35 | G18: 27 | H18: 28.08 | I18: 29.16 | J18: 27.54 | K18: 28.62 | L18: 29.7 | M18: 27.81 | N18: 28.89 | O18: =IF(COUNT(AG18:AP18)>0,MIN(AG18:AP18),"") -> 27 | P18: =IF(COUNT(AG18:AP18)>0,MAX(AG18:AP18),"") -> 29.7 | Q18: =IF(ISNUMBER(O18),P18-O18,"") -> 2.7 | R18: =IF(ISNUMBER(O18),IF(C18="Ручная",IF($S$24>0,$R$24*Q18/$S$24,IF($W$24=7,$R$24,0)),0),"") -> 0.84959016 | S18: =IF(ISNUMBER(O18),O18+R18,"") -> 27.84959 | T18: =IF(ISNUMBER(S18),P18-S18,"") -> 1.8504098 | U18: =IF(COUNT(AG18:AP18)>0,AVERAGE(AG18:AP18),"") -> 28.242 | AG18: =IF(ISNUMBER(E$24),E18,"") -> 27.27 | AH18: =IF(ISNUMBER(F$24),F18,"") -> 28.35 | AI18: =IF(ISNUMBER(G$24),G18,"") -> 27 | AJ18: =IF(ISNUMBER(H$24),H18,"") -> 28.08 | AK18: =IF(ISNUMBER(I$24),I18,"") -> 29.16 | AL18: =IF(ISNUMBER(J$24),J18,"") -> 27.54 | AM18: =IF(ISNUMBER(K$24),K18,"") -> 28.62 | AN18: =IF(ISNUMBER(L$24),L18,"") -> 29.7 | ... AP18: =IF(ISNUMBER(N$24),N18,"") -> 28.89 | AQ18: =IF(C18="Ручная",O18,0) -> 27
